Workbook

Sheet Summary
A1: Full-text methodological quality appraisal — 78-paper SLR corpus
A3: Scores: 1 = clearly demonstrated; 0.5 = partially demonstrated; 0 = not demonstrated.
A7: Criterion | B7: Mean | C7: Score 1 | D7: Score 0.5 | E7: Score 0
A8: Q1 Methodological reporting | B8: =AVERAGE(Scores!H2:H1048576) -> 0.94871795 | C8: =COUNTIF(Scores!H2:H1048576,1) -> 70 | D8: =COUNTIF(Scores!H2:H1048576,0.5) -> 8 | E8: =COUNTIF(Scores!H2:H1048576,0) -> 0
A9: Q2 Data / evidence base | B9: =AVERAGE(Scores!I2:I1048576) -> 0.94230769 | C9: =COUNTIF(Scores!I2:I1048576,1) -> 69 | D9: =COUNTIF(Scores!I2:I1048576,0.5) -> 9 | E9: =COUNTIF(Scores!I2:I1048576,0) -> 0
A10: Q3 Research design | B10: =AVERAGE(Scores!J2:J1048576) -> 0.96153846 | C10: =COUNTIF(Scores!J2:J1048576,1) -> 72 | D10: =COUNTIF(Scores!J2:J1048576,0.5) -> 6 | E10: =COUNTIF(Scores!J2:J1048576,0) -> 0
A11: Q4 Validation | B11: =AVERAGE(Scores!K2:K1048576) -> 0.88461538 | C11: =COUNTIF(Scores!K2:K1048576,1) -> 66 | D11: =COUNTIF(Scores!K2:K1048576,0.5) -> 6 | E11: =COUNTIF(Scores!K2:K1048576,0) -> 6
A12: Q5 Robustness | B12: =AVERAGE(Scores!L2:L1048576) -> 0.66666667 | C12: =COUNTIF(Scores!L2:L1048576,1) -> 38 | D12: =COUNTIF(Scores!L2:L1048576,0.5) -> 28 | E12: =COUNTIF(Scores!L2:L1048576,0) -> 12
A13: Q6 Analysis-conclusion alignment | B13: =AVERAGE(Scores!M2:M1048576) -> 0.92948718 | C13: =COUNTIF(Scores!M2:M1048576,1) -> 67 | D13: =COUNTIF(Scores!M2:M1048576,0.5) -> 11 | E13: =COUNTIF(Scores!M2:M1048576,0) -> 0
A14: Q7 Reproducibility | B14: =AVERAGE(Scores!N2:N1048576) -> 0.62820513 | C14: =COUNTIF(Scores!N2:N1048576,1) -> 26 | D14: =COUNTIF(Scores!N2:N1048576,0.5) -> 46 | E14: =COUNTIF(Scores!N2:N1048576,0) -> 6
A15: Q8 Study limitations | B15: =AVERAGE(Scores!O2:O1048576) -> 0.57051282 | C15: =COUNTIF(Scores!O2:O1048576,1) -> 31 | D15: =COUNTIF(Scores!O2:O1048576,0.5) -> 27 | E15: =COUNTIF(Scores!O2:O1048576,0) -> 20

Sheet Scores
A1: ID | B1: Ref | C1: Title | D1: Year | E1: Venue | F1: Search stream | G1: Study type | H1: Q1 Reporting | I1: Q2 Data/evidence | J1: Q3 Design | K1: Q4 Validation | L1: Q5 Robustness | M1: Q6 Support | N1: Q7 Reproducibility | O1: Q8 Limitations | P1: Total / 8 | Q1: Average
A2: 1 | B2: \cite{park_stock_2022} | C2: Stock market forecasting using a multi-task approach integrating long short-term memory and the random forest framework | D2: 2022.0 | E2: Applied Soft Computing | F2: Financial | G2: Empirical application | H2: 1 | I2: 1 | J2: 1 | K2: 1 | L2: 1 | M2: 1 | N2: 1 | O2: 1 | P2: =SUM(H2:O2) -> 8 | Q2: =P2/8 -> 1
A3: 2 | B3: \cite{giudici_explainable_2024} | C3: Explainable Artificial Intelligence methods for financial time series | D3: 2024.0 | E3: Physica A: Statistical Mechanics and its Applications | F3: Financial | G3: Methodological / XAI evaluation | H3: 1 | I3: 1 | J3: 1 | K3: 1 | L3: 1 | M3: 1 | N3: 0.5 | O3: 0.5 | P3: =SUM(H3:O3) -> 7 | Q3: =P3/8 -> 0.875
A4: 3 | B4: \cite{parente_profitable_2024} | C4: A profitable trading algorithm for cryptocurrencies using a Neural Network model | D4: 2024.0 | E4: Expert Systems with Applications | F4: Financial | G4: Empirical application | H4: 1 | I4: 1 | J4: 1 | K4: 1 | L4: 1 | M4: 1 | N4: 0.5 | O4: 0.5 | P4: =SUM(H4:O4) -> 7 | Q4: =P4/8 -> 0.875
A5: 4 | B5: \cite{valensky_evaluating_2023} | C5: Evaluating Transparency: A Cross-Model Exploration of Explainable AI in Financial Forecasting | D5: 2023.0 | E5: Proc. IEEE Asia-Pacific Conf. Comput. Sci. Data Eng., CSDE | F5: Financial | G5: Methodological / XAI evaluation | H5: 1 | I5: 1 | J5: 1 | K5: 1 | L5: 0.5 | M5: 1 | N5: 0.5 | O5: 1 | P5: =SUM(H5:O5) -> 7 | Q5: =P5/8 -> 0.875
A6: 5 | B6: \cite{mienye_deep_2024} | C6: Deep Learning in Finance: A Survey of Applications and Techniques | D6: 2024.0 | E6: AI (Switzerland) | F6: Financial | G6: Review / survey | H6: 0.5 | I6: 0.5 | J6: 0.5 | K6: 0 | L6: 0 | M6: 0.5 | N6: 0 | O6: 0 | P6: =SUM(H6:O6) -> 2 | Q6: =P6/8 -> 0.25
A7: 6 | B7: \cite{weber_applications_2024} | C7: Applications of Explainable Artificial Intelligence in Finance—a systematic review of Finance, Information Systems, and Computer Science literature | D7: 2024.0 | E7: Management Review Quarterly | F7: Financial | G7: Review / survey | H7: 1 | I7: 1 | J7: 1 | K7: 0.5 | L7: 0 | M7: 1 | N7: 1 | O7: 1 | P7: =SUM(H7:O7) -> 6.5 | Q7: =P7/8 -> 0.8125
A8: 7 | B8: \cite{deng_high-frequency_2022} | C8: High-Frequency Direction Forecasting of the Futures Market Using a Machine-Learning-Based Method | D8: 2022.0 | E8: Future Internet | F8: Financial | G8: Empirical application | H8: 1 | I8: 1 | J8: 1 | K8: 1 | L8: 0.5 | M8: 1 | N8: 0.5 | O8: 0 | P8: =SUM(H8:O8) -> 6 | Q8: =P8/8 -> 0.75
A9: 8 | B9: \cite{cau_supporting_2023} | C9: Supporting High-Uncertainty Decisions through AI and Logic-Style Explanations | D9: 2023.0 | E9: Int Conf Intell User Interfaces Proc IUI | F9: Financial | G9: Methodological / XAI evaluation | H9: 1 | I9: 1 | J9: 1 | K9: 1 | L9: 0.5 | M9: 1 | N9: 0.5 | O9: 1 | P9: =SUM(H9:O9) -> 7 | Q9: =P9/8 -> 0.875
A10: 9 | B10: \cite{freeborough_investigating_2022} | C10: Investigating Explainability Methods in Recurrent Neural Network Architectures for Financial Time Series Data | D10: 2022.0 | E10: Applied Sciences (Switzerland) | F10: Financial | G10: Methodological / XAI evaluation | H10: 1 | I10: 1 | J10: 1 | K10: 1 | L10: 0.5 | M10: 1 | N10: 1 | O10: 1 | P10: =SUM(H10:O10) -> 7.5 | Q10: =P10/8 -> 0.9375
A11: 10 | B11: \cite{abdullah_explainable_2024} | C11: Explainable deep learning model for stock price forecasting using textual analysis | D11: 2024.0 | E11: Expert Systems with Applications | F11: Financial | G11: Empirical application | H11: 1 | I11: 1 | J11: 1 | K11: 1 | L11: 1 | M11: 1 | N11: 0.5 | O11: 1 | P11: =SUM(H11:O11) -> 7.5 | Q11: =P11/8 -> 0.9375
A12: 11 | B12: \cite{nguyen_robust_2024} | C12: Robust explainer recommendation for time series classification | D12: 2024.0 | E12: Data Min. Knowl. Discov. | F12: All Fields | G12: Methodological / XAI evaluation | H12: 1 | I12: 1 | J12: 1 | K12: 1 | L12: 1 | M12: 1 | N12: 1 | O12: 0.5 | P12: =SUM(H12:O12) -> 7.5 | Q12: =P12/8 -> 0.9375
A13: 12 | B13: \cite{szostak_contextual_2025} | C13: Contextual Background Estimation for Explainable AI in Temperature Prediction | D13: 2025.0 | E13: Appl. Sci. | F13: All Fields | G13: Methodological / XAI evaluation | H13: 1 | I13: 1 | J13: 1 | K13: 1 | L13: 0.5 | M13: 1 | N13: 1 | O13: 0.5 | P13: =SUM(H13:O13) -> 7 | Q13: =P13/8 -> 0.875
... A48: 47 | B48: \cite{saifullah_privacy-explainability_2024} | C48: The privacy-explainability trade-off: unraveling the impacts of differential privacy and federated learning on attribution methods | D48: 2024.0 | E48: Frontier. Artif. Intell. | F48: All Fields | G48: Methodological / XAI evaluation | H48: 1 | I48: 1 | J48: 1 | K48: 1 | L48: 1 | M48: 1 | N48: 1 | O48: 1 | P48: =SUM(H48:O48) -> 8 | Q48: =P48/8 -> 1
A49: 48 | C49: Problems with Shapley-value-based explanations as feature importance measures | D49: 2020 | F49: Other | G49: Conceptual / theoretical | H49: 1 | I49: 1 | J49: 1 | K49: 1 | L49: 0.5 | M49: 1 | N49: 0.5 | O49: 0 | P49: =SUM(H49:O49) -> 6 | Q49: =P49/8 -> 0.75
A50: 49 | C50: Why model why? Assessing the strengths and limitations of LIME | D50: 2020 | F50: Other | G50: Empirical application | H50: 1 | I50: 1 | J50: 1 | K50: 1 | L50: 1 | M50: 1 | N50: 1 | O50: 0 | P50: =SUM(H50:O50) -> 7 | Q50: =P50/8 -> 0.875
A51: 50 | C51: A Perspective on Explainable Artificial Intelligence Methods: SHAP and LIME | D51: 2025 | F51: Other | G51: Conceptual / theoretical | H51: 1 | I51: 0.5 | J51: 1 | K51: 0.5 | L51: 0.5 | M51: 1 | N51: 1 | O51: 0 | P51: =SUM(H51:O51) -> 5.5 | Q51: =P51/8 -> 0.6875
A52: 51 | C52: The Inadequacy of Shapley Values for Explainability | D52: 2023 | F52: Other | G52: Conceptual / theoretical | H52: 1 | I52: 1 | J52: 1 | K52: 1 | L52: 1 | M52: 1 | N52: 0.5 | O52: 0 | P52: =SUM(H52:O52) -> 6.5 | Q52: =P52/8 -> 0.8125
A53: 52 | C53: On the failings of Shapley values for explainability | D53: 2024 | E53: International Journal of Approximate Reasoning | F53: Other | G53: Conceptual / theoretical | H53: 1 | I53: 1 | J53: 1 | K53: 1 | L53: 1 | M53: 1 | N53: 1 | O53: 0 | P53: =SUM(H53:O53) -> 7 | Q53: =P53/8 -> 0.875
A54: 53 | C54: Rethinking the Role of Gradient-based Attribution Methods for Model Interpretability | D54: 2020 | F54: Other | G54: Methodological / XAI evaluation | H54: 1 | I54: 1 | J54: 1 | K54: 1 | L54: 1 | M54: 1 | N54: 0.5 | O54: 0.5 | P54: =SUM(H54:O54) -> 7 | Q54: =P54/8 -> 0.875
A55: 54 | B55: \cite{fatemi_finvision_2024} | C55: FinVision: A Multi-Agent Framework for Stock Market Prediction | D55: 2024.0 | E55: Proceedings of the 5th ACM International Conference on AI in Finance | F55: Financial | G55: Empirical application | H55: 1 | I55: 1 | J55: 1 | K55: 1 | L55: 1 | M55: 1 | N55: 0.5 | O55: 0.5 | P55: =SUM(H55:O55) -> 7 | Q55: =P55/8 -> 0.875
A56: 55 | B56: \cite{arsenault_survey_2024} | C56: A Survey of Explainable Artificial Intelligence (XAI) in Financial Time Series Forecasting | D56: 2024.0 | F56: Financial | G56: Review / survey | H56: 0.5 | I56: 0.5 | J56: 0.5 | K56: 0 | L56: 0 | M56: 0.5 | N56: 0 | O56: 0 | P56: =SUM(H56:O56) -> 2 | Q56: =P56/8 -> 0.25
A57: 56 | B57: \cite{misheva_hypothesis_2023} | C57: A Hypothesis on Good Practices for AI-based Systems for Financial Time Series Forecasting: Towards Domain-Driven XAI Methods | D57: 2023.0 | F57: Financial | G57: Conceptual / theoretical | H57: 0.5 | I57: 0.5 | J57: 0.5 | K57: 0 | L57: 0 | M57: 0.5 | N57: 0 | O57: 0 | P57: =SUM(H57:O57) -> 2 | Q57: =P57/8 -> 0.25
A58: 57 | B58: \cite{ghimire_timetrail_2023} | C58: TimeTrail: Unveiling Financial Fraud Patterns through Temporal Correlation Analysis | D58: 2023.0 | F58: Financial | G58: Methodological / XAI evaluation | H58: 1 | I58: 1 | J58: 1 | K58: 1 | L58: 0.5 | M58: 0.5 | N58: 0.5 | O58: 0.5 | P58: =SUM(H58:O58) -> 6 | Q58: =P58/8 -> 0.75
A59: 58 | B59: \cite{neri_how_2020} | C59: How to Identify Investor's types in real financial markets by means of agent based simulation | D59: 2020.0 | F59: Financial | G59: Empirical application | H59: 1 | I59: 1 | J59: 1 | K59: 1 | L59: 0.5 | M59: 1 | N59: 0.5 | O59: 1 | P59: =SUM(H59:O59) -> 7 | Q59: =P59/8 -> 0.875
A60: 59 | B60: \cite{philps_making_2019} | C60: Making Good on LSTMs' Unfulfilled Promise | D60: 2019.0 | F60: Financial | G60: Empirical application | H60: 1 | I60: 1 | J60: 1 | K60: 1 | L60: 1 | M60: 1 | N60: 0.5 | O60: 0.5 | P60: =SUM(H60:O60) -> 7 | Q60: =P60/8 -> 0.875
A61: 60 | B61: \cite{matsunaga_exploring_2019} | C61: Exploring Graph Neural Networks for Stock Market Predictions with Rolling Window Analysis | D61: 2019.0 | F61: Financial | G61: Empirical application | H61: 1 | I61: 1 | J61: 1 | K61: 1 | L61: 0.5 | M61: 1 | N61: 1 | O61: 0 | P61: =SUM(H61:O61) -> 6.5 | Q61: =P61/8 -> 0.8125
A62: 61 | B62: \cite{kumar_opening_2017} | C62: Opening the Black Box of Financial AI with CLEAR-Trade: A CLass-Enhanced Attentive Response Approach for Explaining and Visualizing Deep Learning-Driven Stock Market Prediction | D62: 2017.0 | F62: Financial | G62: Methodological / XAI evaluation | H62: 0.5 | I62: 0.5 | J62: 0.5 | K62: 0.5 | L62: 0 | M62: 0.5 | N62: 0 | O62: 0 | P62: =SUM(H62:O62) -> 2.5 | Q62: =P62/8 -> 0.3125
A63: 62 | C63: Explainable AI for Time Series Classification: A Review, Taxonomy and Research Directions | D63: 2022 | E63: IEEE Access | F63: Other | G63: Review / survey | H63: 0.5 | I63: 0.5 | J63: 1 | K63: 0.5 | L63: 0 | M63: 1 | N63: 0.5 | O63: 0 | P63: =SUM(H63:O63) -> 4 | Q63: =P63/8 -> 0.5
A64: 63 | C64: Benchmarking Deep Learning Interpretability in Time Series Predictions | D64: 2020 | E64: Advances in Neural Information Processing Systems | F64: Other | G64: Methodological / XAI evaluation | H64: 1 | I64: 1 | J64: 1 | K64: 1 | L64: 1 | M64: 1 | N64: 1 | O64: 0.5 | P64: =SUM(H64:O64) -> 7.5 | Q64: =P64/8 -> 0.9375
A65: 64 | C65: Explainable Artificial Intelligence (XAI) 2.0: A manifesto of open challenges and interdisciplinary research directions | D65: 2024 | E65: Information Fusion | F65: Other | G65: Conceptual / theoretical | H65: 0.5 | I65: 0.5 | J65: 0.5 | K65: 0 | L65: 0 | M65: 0.5 | N65: 0 | O65: 0 | P65: =SUM(H65:O65) -> 2 | Q65: =P65/8 -> 0.25
A66: 65 | C66: Interpretation of Time-Series Deep Models: A Survey | D66: 2023 | F66: Other | G66: Review / survey | H66: 0.5 | I66: 0.5 | J66: 1 | K66: 0 | L66: 0 | M66: 1 | N66: 0.5 | O66: 0 | P66: =SUM(H66:O66) -> 3.5 | Q66: =P66/8 -> 0.4375
A67: 66 | C67: The Explanation Game: Explaining Machine Learning Models with Cooperative Game Theory | D67: 2019 | F67: Other | G67: Conceptual / theoretical | H67: 1 | I67: 1 | J67: 1 | K67: 1 | L67: 1 | M67: 1 | N67: 1 | O67: 0.5 | P67: =SUM(H67:O67) -> 7.5 | Q67: =P67/8 -> 0.9375
A68: 67 | B68: \cite{cao_ister_2024} | C68: Ister: Inverted Seasonal-Trend Decomposition Transformer for Explainable Multivariate Time Series Forecasting | D68: 2024.0 | F68: All Fields | G68: Methodological / XAI evaluation | H68: 1 | I68: 1 | J68: 1 | K68: 1 | L68: 1 | M68: 1 | N68: 0.5 | O68: 1 | P68: =SUM(H68:O68) -> 7.5 | Q68: =P68/8 -> 0.9375
A69: 68 | B69: \cite{chakraborty_edformer_2024} | C69: EDformer: Embedded Decomposition Transformer for Interpretable Multivariate Time Series Predictions | D69: 2024.0 | F69: All Fields | G69: Methodological / XAI evaluation | H69: 1 | I69: 1 | J69: 1 | K69: 1 | L69: 0.5 | M69: 1 | N69: 0.5 | O69: 0 | P69: =SUM(H69:O69) -> 6 | Q69: =P69/8 -> 0.75
A70: 69 | B70: \cite{brusch_flextime_2024} | C70: FLEXtime: Filterbank learning to explain time series | D70: 2024.0 | F70: All Fields | G70: Methodological / XAI evaluation | H70: 1 | I70: 1 | J70: 1 | K70: 1 | L70: 1 | M70: 1 | N70: 0.5 | O70: 1 | P70: =SUM(H70:O70) -> 7.5 | Q70: =P70/8 -> 0.9375
A71: 70 | B71: \cite{rezaei_explanation_2024} | C71: Explanation Space: A New Perspective into Time Series Interpretability | D71: 2024.0 | F71: All Fields | G71: Methodological / XAI evaluation | H71: 1 | I71: 1 | J71: 1 | K71: 1 | L71: 1 | M71: 1 | N71: 0.5 | O71: 0.5 | P71: =SUM(H71:O71) -> 7 | Q71: =P71/8 -> 0.875
A72: 71 | B72: \cite{brusch_freqrise_2024} | C72: FreqRISE: Explaining time series using frequency masking | D72: 2024.0 | F72: All Fields | G72: Methodological / XAI evaluation | H72: 1 | I72: 1 | J72: 1 | K72: 1 | L72: 1 | M72: 1 | N72: 1 | O72: 1 | P72: =SUM(H72:O72) -> 8 | Q72: =P72/8 -> 1
A73: 72 | B73: \cite{serramazza_improving_2024} | C73: Improving the Evaluation and Actionability of Explanation Methods for Multivariate Time Series Classification | D73: 2024.0 | F73: All Fields | G73: Methodological / XAI evaluation | H73: 1 | I73: 1 | J73: 1 | K73: 1 | L73: 1 | M73: 1 | N73: 1 | O73: 0.5 | P73: =SUM(H73:O73) -> 7.5 | Q73: =P73/8 -> 0.9375
A74: 73 | B74: \cite{xu_kolmogorov-arnold_2024} | C74: Kolmogorov-Arnold Networks for Time Series: Bridging Predictive Power and Interpretability | D74: 2024.0 | F74: All Fields | G74: Methodological / XAI evaluation | H74: 1 | I74: 1 | J74: 1 | K74: 1 | L74: 0.5 | M74: 1 | N74: 0.5 | O74: 1 | P74: =SUM(H74:O74) -> 7 | Q74: =P74/8 -> 0.875
...

Sheet Methodology
A1: Full-text appraisal methodology
A3: The common framework is interpreted according to study type: empirical papers are assessed using datasets/experiments; review papers using their literature corpus/search/synthesis; conceptual/theoretical papers using formal arguments, examples, simulations, or supporting literature. Q4 (validation) is therefore study-type dependent.
A8: ID | B8: Dimension | C8: Criterion | D8: Question | E8: Scoring
A9: Q1 | B9: Reporting | C9: Methodological reporting | D9: Are the methodological approach and key analytical procedures clearly described? | E9: 1 = clearly demonstrated; 0.5 = partially demonstrated; 0 = not demonstrated.
A10: Q2 | B10: Reporting | C10: Data / evidence base | D10: Is the data or evidence base appropriate for the study objective and adequately described? | E10: 1 = clearly demonstrated; 0.5 = partially demonstrated; 0 = not demonstrated.
A11: Q3 | B11: Rigor | C11: Research design | D11: Is the research/experimental design appropriate for addressing the stated objective? | E11: 1 = clearly demonstrated; 0.5 = partially demonstrated; 0 = not demonstrated.
A12: Q4 | B12: Rigor | C12: Validation | D12: Are the findings or model outputs evaluated using an appropriate validation procedure for the type of study? | E12: 1 = clearly demonstrated; 0.5 = partially demonstrated; 0 = not demonstrated.
A13: Q5 | B13: Rigor | C13: Robustness | D13: Does the study assess whether its main findings are robust to relevant alternative specifications, conditions, data, methods, or assumptions? | E13: 1 = clearly demonstrated; 0.5 = partially demonstrated; 0 = not demonstrated.
A14: Q6 | B14: Credibility | C14: Analysis-conclusion alignment | D14: Do the analyses and evidence presented adequately support the conclusions drawn? | E14: 1 = clearly demonstrated; 0.5 = partially demonstrated; 0 = not demonstrated.
A15: Q7 | B15: Credibility | C15: Reproducibility | D15: Is sufficient information provided to reproduce, reconstruct, or trace how the findings were obtained? | E15: 1 = clearly demonstrated; 0.5 = partially demonstrated; 0 = not demonstrated.
A16: Q8 | B16: Credibility | C16: Study limitations | D16: Does the study discuss relevant limitations, assumptions, or threats to the validity of its own findings? | E16: 1 = clearly demonstrated; 0.5 = partially demonstrated; 0 = not demonstrated.
A18: Interpretation rules: Q4 for predictive empirical studies requires a suitable held-out/out-of-sample, temporal, external, benchmark, or equivalent validation; for XAI-method papers it can be ground truth, faithfulness/stability testing, human/domain evaluation, or comparison with competing explainers; for reviews it concerns reliability/appraisal of the synthesis; for theoretical/conceptual papers it can be formal proof, counterexample, simulation, or empirical illustration. Q5 requires evidence beyond the single primary evaluation. Q8 counts limitations of the paper's own study, not merely limitations of SHAP/LIME/XAI in general.
A23: Methodological precedent | B23: Value
A24: Primary precedent | B24: Newcomb & Ochoa (2026), Frontiers in Artificial Intelligence
A25: URL | B25: https://www.frontiersin.org/journals/artificial-intelligence/articles/10.3389/frai.2026.1749956/full
A26: Role of appraisal | B26: Post-inclusion characterization of methodological quality; no retrospective exclusion threshold.
